Workbook

Sheet angajati
A1: id_angajat | B1: nume | C1: prenume | D1: gen | E1: data_nasterii | F1: data_angajarii | G1: id_departament | H1: functie | I1: nivel | J1: oras | K1: tip_contract | L1: salariu_brut_lunar | M1: status | N1: data_plecarii | O1: motiv_plecare | P1: email
A2: 1081 | B2: VOICU | C2: Bianca | D2: F | E2: 29381 | F2: 43120 | G2: 60 | H2: Manager Suport Clienți | I2: Manager | J2: București | K2: Full-time | M2: Plecat | N2: 45006 | O2: Relația cu managerul | P2: bianca.voicu081@technova.ro
A3: 1074 | B3: Nistor | C3: Cristian | D3: Masculin | E3: 35862 | F3: 45497 | G3: 60 | H3: Operator Call Center | I3: Mid | J3: Timișoara | K3: Full-time | L3: 4100 | M3: Activ | P3: cristian.nistor074@technova.ro
A4: 1135 | B4: Voicu | C4: Radu | D4: M | E4: 27401 | F4: 43248 | G4: 70 | H4: Coordonator Logistică | I4: Senior | J4: București | K4: Part-time | L4: 7800 | M4: Activ | P4: radu.voicu135@technova.ro
A5: 1473 | B5: Popescu | C5: Florin | D5: M | E5: 34233 | F5: 43666 | G5: 10 | H5: Tester QA | I5: Junior | J5: Cluj-Napoca | K5: Full-time | L5: 6100 | M5: Activ | P5: florin.popescu473@technova.ro
A6: 1145 | B6: Constantin | C6: Florin | D6: M | E6: 34452 | F6: 44808 | G6: 10 | H6: Analist IT | I6: Senior | J6: București | K6: Full-time | L6: 14500 | M6: Activ | P6: florin.constantin145@technova.ro
A7: 1038 | B7: Constantin | C7: Simona | D7: F | E7: 33039 | F7: 42929 | G7: 60 | H7: Manager Suport Clienți | I7: Manager | J7: Iași | K7: Full-time | L7: 8000 | M7: Activ | P7: simona.constantin038@technova.ro
A8: 1167 | B8: Barbu | C8: Cristian | D8: M | E8: 28122 | F8: 45662 | G8: 30 | H8: Content Creator | I8: Mid | J8: București | K8: Part-time | L8: 5950 | M8: Activ | P8: cristian.barbu167@technova.ro
A9: 1106 | B9: Sandu | C9: Andreea | D9: F | E9: 32723 | F9: 45296 | G9: 20 | H9: Manager Vânzări | I9: Manager | J9: bucuresti | K9: Full-time | L9: 11700 | M9: Plecat | N9: 45811 | O9: Relocare | P9: andreea.sandu106@technova.ro
A10: 1082 | B10: Matei | C10: Ana | D10: F | E10: 29015 | F10: 43499 | G10: 70 | H10: Coordonator Logistică | I10: Senior | J10: Timișoara | K10: Full-time | L10: 6300 | M10: Activ | P10: ana.matei082@technova.ro
A11: 1282 | B11: Preda | C11: Ana | D11: F | E11: 32317 | F11: 45792 | G11: 20 | H11: Agent Vânzări | I11: Mid | J11: București | K11: Full-time | L11: 5650 | M11: Activ | P11: ana.preda282@technova.ro
A12: 1189 | B12: Florea | C12: Florin | D12: M | E12: 32560 | F12: 43703 | G12: 50 | H12: Contabil | I12: Senior | J12: București | K12: Full-time | L12: 10200 | M12: Activ | P12: florin.florea189@technova.ro
A13: 1225 | B13: Marin | C13: Simona | D13: F | E13: 32621 | F13: 43376 | G13: 70 | H13: Manager Operațiuni | I13: Manager | J13: Timișoara | K13: Full-time | L13: 9550 | M13: Activ | P13: simona.marin225@technova.ro
A14: 1133 | B14: CONSTANTIN | C14: Ana | D14: F | E14: 34006 | F14: 43835 | G14: 60 | H14: Specialist Suport | I14: Junior | J14: Iași | K14: Full-time | L14: 2750 | M14: Activ | P14: ana.constantin133@technova.ro
A15: 1267 | B15: Ionescu | C15: Mihai | D15: M | E15: 32646 | F15: 42689 | G15: 30 | H15: Content Creator | I15: Mid | J15: Cluj-Napoca | K15: Full-time | L15: 6700 | M15: Activ | P15: mihai.ionescu267@technova.ro
A16: 1137 | B16: Voicu | C16: Bianca | D16: F | E16: 27309 | F16: 45771 | G16: 30 | H16: Content Creator | I16: Senior | J16: București | K16: Part-time | L16: 8900 | M16: Activ | P16: bianca.voicu137@technova.ro
A17: 1365 | B17: Stoica | C17: Radu | D17: M | E17: 32316 | F17: 45097 | G17: 70 | H17: Coordonator Logistică | I17: Junior | J17: Timișoara | K17: Full-time | L17: 3200 | M17: Activ | P17: radu.stoica365@technova.ro
A18: 1475 | B18: Constantin | C18: Bianca | D18: F | E18: 29213 | F18: 42724 | G18: 10 | H18: Programator | I18: Senior | J18: București | K18: Full-time | L18: 12350 | M18: Activ | P18: bianca.constantin475@technova.ro
A19: 1028 | B19: Oprea | C19: Diana | D19: F | E19: 29943 | F19: 43945 | G19: 70 | H19: Coordonator Logistică | I19: Mid | J19: Timișoara | K19: Full-time | L19: 4550 | M19: Activ | P19: diana.oprea028@technova.ro
A20: 1274 | B20: Dobre | C20: Simona | D20: F | E20: 33086 | F20: 44939 | G20: 10 | H20: Programator | I20: Mid | J20: București | K20: Full-time | L20: 9200 | M20: Activ | P20: simona.dobre274@technova.ro
A21: 1333 | B21: Stan | C21: Robert | D21: m | E21: 34085 | F21: 44036 | G21: 60 | H21: Specialist Suport | I21: Mid | J21: Iași | K21: Full-time | L21: 4300 | M21: Activ | P21: robert.stan333@technova.ro
... A23: 1191 | B23: Munteanu | C23: Bianca | D23: F | E23: 27885 | F23: 45518 | G23: 40 | H23: Specialist HR | I23: Mid | J23: București | K23: Full-time | L23: 6100 | M23: Activ | P23: bianca.munteanu191@technova.ro
A24: 1322 | B24: Stan | C24: Robert | D24: M | E24: 30718 | F24: 42689 | G24: 20 | H24: Key Account Manager | I24: Mid | J24: București | K24: Full-time | L24: 5700 | M24: Plecat | N24: 44180 | O24: Salariu mai bun în altă parte | P24: robert.stan322@technova.ro
A25: 1403 | B25: Popescu | C25: Ionuț | D25: M | E25: 27222 | F25: 43492 | G25: 10 | H25: DevOps Engineer | I25: Senior | J25: București | K25: Full-time | L25: 14650 | M25: Activ | P25: ionut.popescu403@technova.ro
A26: 1058 | B26: Ionescu | C26: Bogdan | D26: M | E26: 28282 | F26: 43315 | G26: 70 | H26: Coordonator Logistică | I26: Senior | J26: Timișoara | K26: Full-time | L26: 8150 | M26: Activ | P26: bogdan.ionescu058@technova.ro
A27: 1300 | B27: Dinu | C27: Marius | D27: M | E27: 36678 | F27: 44467 | G27: 30 | H27: Content Creator | I27: Junior | J27: Cluj-Napoca | K27: Full-time | L27: 3400 | M27: Activ | P27: marius.dinu300@technova.ro
A28: 1125 | B28: Toma | C28: Robert | D28: M | E28: 35131 | F28: 43222 | G28: 70 | H28: Specialist Operațiuni | I28: Mid | J28: Timișoara | K28: Full-time | L28: 5450 | M28: Plecat | N28: 44578 | O28: Lipsa oportunităților de promovare | P28: robert.toma125@technova.ro
A29: 1318 | B29: Florea | C29: Denisa | D29: F | E29: 29751 | F29: 44298 | G29: 40 | H29: Recruiter | I29: Mid | J29: București | K29: Full-time | L29: 5100 | M29: Activ | P29: denisa.florea318@technova.ro
A30: 1104 | B30: Gheorghe | C30: Diana | D30: F | E30: 33047 | F30: 43639 | G30: 50 | H30: Analist Financiar | I30: Mid | J30: București | K30: Full-time | L30: 6300 | M30: Activ | P30: diana.gheorghe104@technova.ro
A31: 1156 | B31: Lungu | C31: Vlad | D31: M | E31: 35232 | F31: 44888 | G31: 20 | H31: Key Account Manager | I31: Junior | J31: Iași | K31: Full-time | L31: 3450 | M31: Activ | P31: vlad.lungu156@technova.ro
A32: 1261 | B32: Gheorghe | C32: Alexandra | D32: F | E32: 30567 | F32: 44459 | G32: 60 | H32: Specialist Suport | I32: Junior | J32: Iași | K32: Full-time | L32: 2800 | M32: Activ | P32: alexandra.gheorghe261@technova.ro
A33: 1379 | B33: Popescu | C33: Florin | D33: M | E33: 31800 | F33: 42764 | G33: 10 | H33: Programator | I33: Junior | J33: București | K33: Full-time | L33: 5750 | M33: Activ | P33: florin.popescu379@technova.ro
A34: 1160 | B34: Nistor | C34: Roxana | D34: F | E34: 29909 | F34: 44968 | G34: 70 | H34: Coordonator Logistică | I34: Junior | J34: timișoara | K34: Part-time | L34: 3100 | M34: Activ | P34: roxana.nistor160@technova.ro
A35: 1226 | B35: Popa | C35: Cristian | D35: M | E35: 34918 | F35: 42783 | G35: 10 | H35: Tester QA | I35: Junior | J35: Cluj-Napoca | K35: Full-time | L35: 5200 | M35: Activ | P35: cristian.popa226@technova.ro
A36: 1464 | B36: Neagu | C36: Marius | D36: M | E36: 33576 | F36: 43071 | G36: 10 | H36: Programator | I36: Senior | J36: București | K36: Full-time | L36: 12350 | M36: Activ | P36: marius.neagu464@technova.ro
A37: 1389 | B37: DINU | C37: Vlad | D37: M | E37: 34852 | F37: 42928 | G37: 60 | H37: Specialist Suport | I37: Mid | J37: Iași | K37: Full-time | L37: 3900 | M37: Activ | P37: vlad.dinu389@technova.ro
A38: 1339 | B38: Nistor | C38: Sorin | D38: M | E38: 31256 | F38: 43593 | G38: 60 | H38: Specialist Suport | I38: Mid | J38: Iași | K38: Full-time | L38: 4250 | M38: Activ | P38: sorin.nistor339@technova.ro
A39: 1229 | B39: Constantin | C39: Mihai | D39: M | E39: 27503 | F39: 43908 | G39: 50 | H39: Manager Financiar | I39: Manager | J39: Timișoara | K39: Full-time | L39: 14050 | M39: Activ | P39: mihai.constantin229@technova.ro
A40: 1088 | B40: Oprea | C40: Alexandru | D40: M | E40: 31743 | F40: 45600 | G40: 20 | H40: Manager Vânzări | I40: Manager | J40: Iași | K40: Full-time | L40: 9150 | M40: Activ | P40: alexandru.oprea088@technova.ro
... A42: 1463 | B42: Tudor | C42: Ana | D42: Feminin | E42: 30359 | F42: 44724 | G42: 10 | H42: DevOps Engineer | I42: Senior | J42: București | K42: Full-time | L42: 12200 | M42: Activ | P42: ana.tudor463@technova.ro
...

Sheet evaluari
A1: id_evaluare | B1: id_angajat | C1: an_evaluare | D1: scor_performanta | E1: satisfactie_angajat | F1: ore_suplimentare_lunare | G1: ore_training_anual | H1: zile_concediu_medical | I1: procent_bonus
A2: 1 | B2: 1001 | C2: 2023 | D2: 3 | E2: 6 | F2: 2 | G2: 35 | H2: 5 | I2: 4.9
A3: 4 | B3: 1002 | C3: 2023 | D3: 4 | E3: 6 | F3: 0 | G3: 36 | H3: 4 | I3: 7
A4: 7 | B4: 1003 | C4: 2023 | D4: 3 | F4: 9 | G4: 40 | H4: 9 | I4: 4.8
A5: 9 | B5: 1005 | C5: 2023 | D5: 3 | E5: 4 | F5: 16 | G5: 2 | H5: 8 | I5: 5.5
A6: 12 | B6: 1006 | C6: 2023 | D6: 5 | E6: 7 | F6: 0 | G6: 15 | H6: 5 | I6: 12.5
A7: 16 | B7: 1008 | C7: 2023 | D7: 4 | E7: 3 | F7: 0 | G7: 9 | H7: 7 | I7: 8.2
A8: 19 | B8: 1009 | C8: 2023 | D8: 3 | E8: 5 | F8: 10 | G8: 31 | H8: 6 | I8: 6.2
A9: 20 | B9: 1011 | C9: 2023 | D9: 3 | E9: 7 | F9: 7 | G9: 4 | H9: 3 | I9: 5.4
A10: 23 | B10: 1012 | C10: 2023 | D10: 4 | E10: 4 | F10: 6 | G10: 14 | H10: 4 | I10: 8.2
A11: 24 | B11: 1014 | C11: 2023 | D11: 2 | E11: 6 | F11: 9 | G11: 22 | H11: 8 | I11: 1.9
A12: 29 | B12: 1016 | C12: 2023 | D12: 4 | E12: 5 | F12: 4 | G12: 26 | H12: 5 | I12: 8.6
A13: 32 | B13: 1017 | C13: 2023 | D13: 4 | E13: 6 | F13: 1 | G13: 15 | H13: 4 | I13: 9.8
A14: 35 | B14: 1018 | C14: 2023 | D14: 3 | E14: 6 | F14: 15 | G14: 37 | H14: 2 | I14: 4.6
A15: 38 | B15: 1019 | C15: 2023 | D15: 4 | E15: 3 | F15: 10 | G15: 12 | H15: 6 | I15: 7.5
A16: 44 | B16: 1022 | C16: 2023 | D16: 3 | E16: 4 | F16: 14 | G16: 33 | H16: 7 | I16: 4.8
... A23: 65 | B23: 1030 | C23: 2023 | D23: 4 | E23: 4 | F23: 12 | G23: 29 | H23: 12 | I23: 7.6
A24: 68 | B24: 1031 | C24: 2023 | E24: 8 | F24: 12 | G24: 31 | H24: 3 | I24: 9.2
A25: 71 | B25: 1032 | C25: 2023 | D25: 4 | E25: 4 | F25: 0 | G25: 31 | H25: 5 | I25: 6.8
A26: 74 | B26: 1034 | C26: 2023 | D26: 2 | E26: 5 | F26: 0 | G26: 12 | H26: 8 | I26: 2.9
A27: 79 | B27: 1036 | C27: 2023 | D27: 3 | E27: 4 | F27: 10 | G27: 21 | H27: 8 | I27: 5.6
A28: 82 | B28: 1037 | C28: 2023 | D28: 4 | E28: 7 | F28: 16 | G28: 24 | H28: 4 | I28: 8.8
A29: 85 | B29: 1038 | C29: 2023 | D29: 4 | E29: 9 | F29: 9 | G29: 20 | H29: 7 | I29: 9.7
A30: 88 | B30: 1039 | C30: 2023 | D30: 3 | E30: 4 | F30: 7 | G30: 45 | H30: 7 | I30: 4.4
A31: 89 | B31: 1040 | C31: 2023 | D31: 4 | E31: 6 | F31: 25 | G31: 27 | H31: 0 | I31: 9.4
A32: 92 | B32: 1041 | C32: 2023 | D32: 5 | E32: 7 | F32: 8 | G32: 33 | H32: 4 | I32: 12.5
A33: 95 | B33: 1043 | C33: 2023 | D33: 3 | E33: 8 | F33: 7 | G33: 32 | H33: 4 | I33: 5.9
A34: 100 | B34: 1045 | C34: 2023 | D34: 2 | E34: 1 | F34: 1 | G34: 6 | H34: 11 | I34: 1.2
A35: 103 | B35: 1046 | C35: 2023 | D35: 3 | E35: 6 | F35: 11 | G35: 31 | H35: 3 | I35: 3.2
A36: 106 | B36: 1047 | C36: 2023 | D36: 4 | E36: 6 | F36: 2 | G36: 21 | H36: 8 | I36: 7.5
... A61: 193 | B61: 1082 | C61: 2023 | D61: 4 | E61: 7 | F61: 1 | G61: 27 | H61: 6 | I61: 7.8
A62: 196 | B62: 1083 | C62: 2023 | F62: 9 | G62: 43 | H62: 1 | I62: 13.1
A63: 199 | B63: 1084 | C63: 2023 | D63: 4 | E63: 6 | F63: 11 | G63: 20 | H63: 5 | I63: 8
A64: 202 | B64: 1085 | C64: 2023 | D64: 4 | E64: 5 | F64: 10 | G64: 22 | H64: 7 | I64: 7.6
A65: 203 | B65: 1086 | C65: 2023 | D65: 3 | E65: 7 | F65: 10 | G65: 30 | H65: 6 | I65: 4.2
A66: 206 | B66: 1087 | C66: 2023 | D66: 5 | E66: 6 | F66: 13 | G66: 33 | H66: 4 | I66: 13.2
A67: 211 | B67: 1089 | C67: 2023 | D67: 5 | E67: 6 | F67: 1 | G67: 28 | H67: 4 | I67: 13.1
A68: 216 | B68: 1092 | C68: 2023 | D68: 3 | E68: 10 | F68: 10 | G68: 28 | H68: 2 | I68: 6.4
A69: 220 | B69: 1094 | C69: 2023 | D69: 2 | F69: 1 | G69: 1 | H69: 5 | I69: 3
A70: 223 | B70: 1095 | C70: 2023 | D70: 5 | E70: 5 | F70: 17 | G70: 0 | H70: 6 | I70: 14.1
...

Sheet departamente
A1: id_departament | B1: nume_departament | C1: oras_sediu | D1: buget_anual_lei
A2: 10 | B2: IT | C2: București | D2: 4200000
A3: 20 | B3: Vânzări | C3: București | D3: 3100000
A4: 30 | B4: Marketing | C4: Cluj-Napoca | D4: 1500000
A5: 40 | B5: Resurse Umane | C5: București | D5: 900000
A6: 50 | B6: Financiar | C6: Iași | D6: 1300000
A7: 60 | B7: Suport Clienți | C7: Iași | D7: 2000000
A8: 70 | B8: Operațiuni | C8: Timișoara | D8: 2500000
A9: 80 | B9: Juridic | C9: București | D9: 700000

Sheet angajati_curat
A1: id_angajat | B1: nume | C1: prenume | D1: gen | E1: data_nasterii | F1: data_angajarii | G1: id_departament | H1: functie | I1: nivel | J1: oras | K1: tip_contract | L1: salariu_brut_lunar | M1: status | N1: data_plecarii | O1: motiv_plecare | P1: email | Q1: nume_departament | R1: varsta | S1: vechime_ani | T1: grupa_vechime | U1: plecat
A2: 1081 | B2: Voicu | C2: Bianca | D2: F | E2: 29381 | F2: 43120 | G2: 60 | H2: Manager Suport Clienți | I2: Manager | J2: București | K2: Full-time | L2: 8000 | M2: Plecat | N2: 45006 | O2: Relația cu managerul | P2: bianca.voicu081@technova.ro | Q2: =_xlfn.XLOOKUP(angajati__2[[#This Row],[id_departament]],departamente!A:A,departamente!B:B) -> Suport Clienți | R2: =DATEDIF(E2,DATE(2025,12,31), "y") -> 45 | S2: =ROUND(YEARFRAC(F2, IF(M2="Plecat", N2, DATE(2025,12,31)), 1), 1) -> 5.2 | T2: {=_xlfn.IFS( S2<1, "< 1 an", S2<3, "1–3 ani", S2<5, "3–5 ani", S2>=5, "> 5 ani" )} -> > 5 ani | U2: =IF(M2="Plecat", 1, 0) -> 1
A3: 1074 | B3: Nistor | C3: Cristian | D3: M | E3: 35862 | F3: 45497 | G3: 60 | H3: Operator Call Center | I3: Mid | J3: Timișoara | K3: Full-time | L3: 4100 | M3: Activ | P3: cristian.nistor074@technova.ro | Q3: =_xlfn.XLOOKUP(angajati__2[[#This Row],[id_departament]],departamente!A:A,departamente!B:B) -> Suport Clienți | R3: =DATEDIF(E3,DATE(2025,12,31), "y") -> 27 | S3: =ROUND(YEARFRAC(F3, IF(M3="Plecat", N3, DATE(2025,12,31)), 1), 1) -> 1.4 | T3: {=_xlfn.IFS( S3<1, "< 1 an", S3<3, "1–3 ani", S3<5, "3–5 ani", S3>=5, "> 5 ani" )} -> 1–3 ani | U3: =IF(M3="Plecat", 1, 0) -> 0
A4: 1135 | B4: Voicu | C4: Radu | D4: M | E4: 27401 | F4: 43248 | G4: 70 | H4: Coordonator Logistică | I4: Senior | J4: București | K4: Part-time | L4: 7800 | M4: Activ | P4: radu.voicu135@technova.ro | Q4: =_xlfn.XLOOKUP(angajati__2[[#This Row],[id_departament]],departamente!A:A,departamente!B:B) -> Operațiuni | R4: =DATEDIF(E4,DATE(2025,12,31), "y") -> 50 | S4: =ROUND(YEARFRAC(F4, IF(M4="Plecat", N4, DATE(2025,12,31)), 1), 1) -> 7.6 | T4: {=_xlfn.IFS( S4<1, "< 1 an", S4<3, "1–3 ani", S4<5, "3–5 ani", S4>=5, "> 5 ani" )} -> > 5 ani | U4: =IF(M4="Plecat", 1, 0) -> 0
A5: 1473 | B5: Popescu | C5: Florin | D5: M | E5: 34233 | F5: 43666 | G5: 10 | H5: Tester QA | I5: Junior | J5: Cluj-Napoca | K5: Full-time | L5: 6100 | M5: Activ | P5: florin.popescu473@technova.ro | Q5: =_xlfn.XLOOKUP(angajati__2[[#This Row],[id_departament]],departamente!A:A,departamente!B:B) -> IT | R5: =DATEDIF(E5,DATE(2025,12,31), "y") -> 32 | S5: =ROUND(YEARFRAC(F5, IF(M5="Plecat", N5, DATE(2025,12,31)), 1), 1) -> 6.4 | T5: {=_xlfn.IFS( S5<1, "< 1 an", S5<3, "1–3 ani", S5<5, "3–5 ani", S5>=5, "> 5 ani" )} -> > 5 ani | U5: =IF(M5="Plecat", 1, 0) -> 0
A6: 1145 | B6: Constantin | C6: Florin | D6: M | E6: 34452 | F6: 44808 | G6: 10 | H6: Analist IT | I6: Senior | J6: București | K6: Full-time | L6: 14500 | M6: Activ | P6: florin.constantin145@technova.ro | Q6: =_xlfn.XLOOKUP(angajati__2[[#This Row],[id_departament]],departamente!A:A,departamente!B:B) -> IT | R6: =DATEDIF(E6,DATE(2025,12,31), "y") -> 31 | S6: =ROUND(YEARFRAC(F6, IF(M6="Plecat", N6, DATE(2025,12,31)), 1), 1) -> 3.3 | T6: {=_xlfn.IFS( S6<1, "< 1 an", S6<3, "1–3 ani", S6<5, "3–5 ani", S6>=5, "> 5 ani" )} -> 3–5 ani | U6: =IF(M6="Plecat", 1, 0) -> 0
A7: 1038 | B7: Constantin | C7: Simona | D7: F | E7: 33039 | F7: 42929 | G7: 60 | H7: Manager Suport Clienți | I7: Manager | J7: Iași | K7: Full-time | L7: 8000 | M7: Activ | P7: simona.constantin038@technova.ro | Q7: =_xlfn.XLOOKUP(angajati__2[[#This Row],[id_departament]],departamente!A:A,departamente!B:B) -> Suport Clienți | R7: =DATEDIF(E7,DATE(2025,12,31), "y") -> 35 | S7: =ROUND(YEARFRAC(F7, IF(M7="Plecat", N7, DATE(2025,12,31)), 1), 1) -> 8.5 | T7: {=_xlfn.IFS( S7<1, "< 1 an", S7<3, "1–3 ani", S7<5, "3–5 ani", S7>=5, "> 5 ani" )} -> > 5 ani | U7: =IF(M7="Plecat", 1, 0) -> 0
A8: 1167 | B8: Barbu | C8: Cristian | D8: M | E8: 28122 | F8: 45662 | G8: 30 | H8: Content Creator | I8: Mid | J8: București | K8: Part-time | L8: 5950 | M8: Activ | P8: cristian.barbu167@technova.ro | Q8: =_xlfn.XLOOKUP(angajati__2[[#This Row],[id_departament]],departamente!A:A,departamente!B:B) -> Marketing | R8: =DATEDIF(E8,DATE(2025,12,31), "y") -> 49 | S8: =ROUND(YEARFRAC(F8, IF(M8="Plecat", N8, DATE(2025,12,31)), 1), 1) -> 1 | T8: {=_xlfn.IFS( S8<1, "< 1 an", S8<3, "1–3 ani", S8<5, "3–5 ani", S8>=5, "> 5 ani" )} -> 1–3 ani | U8: =IF(M8="Plecat", 1, 0) -> 0
A9: 1106 | B9: Sandu | C9: Andreea | D9: F | E9: 32723 | F9: 45296 | G9: 20 | H9: Manager Vânzări | I9: Manager | J9: București | K9: Full-time | L9: 11700 | M9: Plecat | N9: 45811 | O9: Relocare | P9: andreea.sandu106@technova.ro | Q9: =_xlfn.XLOOKUP(angajati__2[[#This Row],[id_departament]],departamente!A:A,departamente!B:B) -> Vânzări | R9: =DATEDIF(E9,DATE(2025,12,31), "y") -> 36 | S9: =ROUND(YEARFRAC(F9, IF(M9="Plecat", N9, DATE(2025,12,31)), 1), 1) -> 1.4 | T9: {=_xlfn.IFS( S9<1, "< 1 an", S9<3, "1–3 ani", S9<5, "3–5 ani", S9>=5, "> 5 ani" )} -> 1–3 ani | U9: =IF(M9="Plecat", 1, 0) -> 1
A10: 1082 | B10: Matei | C10: Ana | D10: F | E10: 29015 | F10: 43499 | G10: 70 | H10: Coordonator Logistică | I10: Senior | J10: Timișoara | K10: Full-time | L10: 6300 | M10: Activ | P10: ana.matei082@technova.ro | Q10: =_xlfn.XLOOKUP(angajati__2[[#This Row],[id_departament]],departamente!A:A,departamente!B:B) -> Operațiuni | R10: =DATEDIF(E10,DATE(2025,12,31), "y") -> 46 | S10: =ROUND(YEARFRAC(F10, IF(M10="Plecat", N10, DATE(2025,12,31)), 1), 1) -> 6.9 | T10: {=_xlfn.IFS( S10<1, "< 1 an", S10<3, "1–3 ani", S10<5, "3–5 ani", S10>=5, "> 5 ani" )} -> > 5 ani | U10: =IF(M10="Plecat", 1, 0) -> 0
A11: 1282 | B11: Preda | C11: Ana | D11: F | E11: 32317 | F11: 45792 | G11: 20 | H11: Agent Vânzări | I11: Mid | J11: București | K11: Full-time | L11: 5650 | M11: Activ | P11: ana.preda282@technova.ro | Q11: =_xlfn.XLOOKUP(angajati__2[[#This Row],[id_departament]],departamente!A:A,departamente!B:B) -> Vânzări | R11: =DATEDIF(E11,DATE(2025,12,31), "y") -> 37 | S11: =ROUND(YEARFRAC(F11, IF(M11="Plecat", N11, DATE(2025,12,31)), 1), 1) -> 0.6 | T11: {=_xlfn.IFS( S11<1, "< 1 an", S11<3, "1–3 ani", S11<5, "3–5 ani", S11>=5, "> 5 ani" )} -> < 1 an | U11: =IF(M11="Plecat", 1, 0) -> 0
A12: 1189 | B12: Florea | C12: Florin | D12: M | E12: 32560 | F12: 43703 | G12: 50 | H12: Contabil | I12: Senior | J12: București | K12: Full-time | L12: 10200 | M12: Activ | P12: florin.florea189@technova.ro | Q12: =_xlfn.XLOOKUP(angajati__2[[#This Row],[id_departament]],departamente!A:A,departamente!B:B) -> Financiar | R12: =DATEDIF(E12,DATE(2025,12,31), "y") -> 36 | S12: =ROUND(YEARFRAC(F12, IF(M12="Plecat", N12, DATE(2025,12,31)), 1), 1) -> 6.3 | T12: {=_xlfn.IFS( S12<1, "< 1 an", S12<3, "1–3 ani", S12<5, "3–5 ani", S12>=5, "> 5 ani" )} -> > 5 ani | U12: =IF(M12="Plecat", 1, 0) -> 0
A13: 1225 | B13: Marin | C13: Simona | D13: F | E13: 32621 | F13: 43376 | G13: 70 | H13: Manager Operațiuni | I13: Manager | J13: Timișoara | K13: Full-time | L13: 9550 | M13: Activ | P13: simona.marin225@technova.ro | Q13: =_xlfn.XLOOKUP(angajati__2[[#This Row],[id_departament]],departamente!A:A,departamente!B:B) -> Operațiuni | R13: =DATEDIF(E13,DATE(2025,12,31), "y") -> 36 | S13: =ROUND(YEARFRAC(F13, IF(M13="Plecat", N13, DATE(2025,12,31)), 1), 1) -> 7.2 | T13: {=_xlfn.IFS( S13<1, "< 1 an", S13<3, "1–3 ani", S13<5, "3–5 ani", S13>=5, "> 5 ani" )} -> > 5 ani | U13: =IF(M13="Plecat", 1, 0) -> 0
A14: 1133 | B14: Constantin | C14: Ana | D14: F | E14: 34006 | F14: 43835 | G14: 60 | H14: Specialist Suport | I14: Junior | J14: Iași | K14: Full-time | L14: 2750 | M14: Activ | P14: ana.constantin133@technova.ro | Q14: =_xlfn.XLOOKUP(angajati__2[[#This Row],[id_departament]],departamente!A:A,departamente!B:B) -> Suport Clienți | R14: =DATEDIF(E14,DATE(2025,12,31), "y") -> 32 | S14: =ROUND(YEARFRAC(F14, IF(M14="Plecat", N14, DATE(2025,12,31)), 1), 1) -> 6 | T14: {=_xlfn.IFS( S14<1, "< 1 an", S14<3, "1–3 ani", S14<5, "3–5 ani", S14>=5, "> 5 ani" )} -> > 5 ani | U14: =IF(M14="Plecat", 1, 0) -> 0
A15: 1267 | B15: Ionescu | C15: Mihai | D15: M | E15: 32646 | F15: 42689 | G15: 30 | H15: Content Creator | I15: Mid | J15: Cluj-Napoca | K15: Full-time | L15: 6700 | M15: Activ | P15: mihai.ionescu267@technova.ro | Q15: =_xlfn.XLOOKUP(angajati__2[[#This Row],[id_departament]],departamente!A:A,departamente!B:B) -> Marketing | R15: =DATEDIF(E15,DATE(2025,12,31), "y") -> 36 | S15: =ROUND(YEARFRAC(F15, IF(M15="Plecat", N15, DATE(2025,12,31)), 1), 1) -> 9.1 | T15: {=_xlfn.IFS( S15<1, "< 1 an", S15<3, "1–3 ani", S15<5, "3–5 ani", S15>=5, "> 5 ani" )} -> > 5 ani | U15: =IF(M15="Plecat", 1, 0) -> 0
A16: 1137 | B16: Voicu | C16: Bianca | D16: F | E16: 27309 | F16: 45771 | G16: 30 | H16: Content Creator | I16: Senior | J16: București | K16: Part-time | L16: 8900 | M16: Activ | P16: bianca.voicu137@technova.ro | Q16: =_xlfn.XLOOKUP(angajati__2[[#This Row],[id_departament]],departamente!A:A,departamente!B:B) -> Marketing | R16: =DATEDIF(E16,DATE(2025,12,31), "y") -> 51 | S16: =ROUND(YEARFRAC(F16, IF(M16="Plecat", N16, DATE(2025,12,31)), 1), 1) -> 0.7 | T16: {=_xlfn.IFS( S16<1, "< 1 an", S16<3, "1–3 ani", S16<5, "3–5 ani", S16>=5, "> 5 ani" )} -> < 1 an | U16: =IF(M16="Plecat", 1, 0) -> 0
A17: 1365 | B17: Stoica | C17: Radu | D17: M | E17: 32316 | F17: 45097 | G17: 70 | H17: Coordonator Logistică | I17: Junior | J17: Timișoara | K17: Full-time | L17: 3200 | M17: Activ | P17: radu.stoica365@technova.ro | Q17: =_xlfn.XLOOKUP(angajati__2[[#This Row],[id_departament]],departamente!A:A,departamente!B:B) -> Operațiuni | R17: =DATEDIF(E17,DATE(2025,12,31), "y") -> 37 | S17: =ROUND(YEARFRAC(F17, IF(M17="Plecat", N17, DATE(2025,12,31)), 1), 1) -> 2.5 | T17: {=_xlfn.IFS( S17<1, "< 1 an", S17<3, "1–3 ani", S17<5, "3–5 ani", S17>=5, "> 5 ani" )} -> 1–3 ani | U17: =IF(M17="Plecat", 1, 0) -> 0
A18: 1475 | B18: Constantin | C18: Bianca | D18: F | E18: 29213 | F18: 42724 | G18: 10 | H18: Programator | I18: Senior | J18: București | K18: Full-time | L18: 12350 | M18: Activ | P18: bianca.constantin475@technova.ro | Q18: =_xlfn.XLOOKUP(angajati__2[[#This Row],[id_departament]],departamente!A:A,departamente!B:B) -> IT | R18: =DATEDIF(E18,DATE(2025,12,31), "y") -> 46 | S18: =ROUND(YEARFRAC(F18, IF(M18="Plecat", N18, DATE(2025,12,31)), 1), 1) -> 9 | T18: {=_xlfn.IFS( S18<1, "< 1 an", S18<3, "1–3 ani", S18<5, "3–5 ani", S18>=5, "> 5 ani" )} -> > 5 ani | U18: =IF(M18="Plecat", 1, 0) -> 0
A19: 1028 | B19: Oprea | C19: Diana | D19: F | E19: 29943 | F19: 43945 | G19: 70 | H19: Coordonator Logistică | I19: Mid | J19: Timișoara | K19: Full-time | L19: 4550 | M19: Activ | P19: diana.oprea028@technova.ro | Q19: =_xlfn.XLOOKUP(angajati__2[[#This Row],[id_departament]],departamente!A:A,departamente!B:B) -> Operațiuni | R19: =DATEDIF(E19,DATE(2025,12,31), "y") -> 44 | S19: =ROUND(YEARFRAC(F19, IF(M19="Plecat", N19, DATE(2025,12,31)), 1), 1) -> 5.7 | T19: {=_xlfn.IFS( S19<1, "< 1 an", S19<3, "1–3 ani", S19<5, "3–5 ani", S19>=5, "> 5 ani" )} -> > 5 ani | U19: =IF(M19="Plecat", 1, 0) -> 0
A20: 1274 | B20: Dobre | C20: Simona | D20: F | E20: 33086 | F20: 44939 | G20: 10 | H20: Programator | I20: Mid | J20: București | K20: Full-time | L20: 9200 | M20: Activ | P20: simona.dobre274@technova.ro | Q20: =_xlfn.XLOOKUP(angajati__2[[#This Row],[id_departament]],departamente!A:A,departamente!B:B) -> IT | R20: =DATEDIF(E20,DATE(2025,12,31), "y") -> 35 | S20: =ROUND(YEARFRAC(F20, IF(M20="Plecat", N20, DATE(2025,12,31)), 1), 1) -> 3 | T20: {=_xlfn.IFS( S20<1, "< 1 an", S20<3, "1–3 ani", S20<5, "3–5 ani", S20>=5, "> 5 ani" )} -> 3–5 ani | U20: =IF(M20="Plecat", 1, 0) -> 0
A21: 1333 | B21: Stan | C21: Robert | D21: M | E21: 34085 | F21: 44036 | G21: 60 | H21: Specialist Suport | I21: Mid | J21: Iași | K21: Full-time | L21: 4300 | M21: Activ | P21: robert.stan333@technova.ro | Q21: =_xlfn.XLOOKUP(angajati__2[[#This Row],[id_departament]],departamente!A:A,departamente!B:B) -> Suport Clienți | R21: =DATEDIF(E21,DATE(2025,12,31), "y") -> 32 | S21: =ROUND(YEARFRAC(F21, IF(M21="Plecat", N21, DATE(2025,12,31)), 1), 1) -> 5.4 | T21: {=_xlfn.IFS( S21<1, "< 1 an", S21<3, "1–3 ani", S21<5, "3–5 ani", S21>=5, "> 5 ani" )} -> > 5 ani | U21: =IF(M21="Plecat", 1, 0) -> 0
... A23: 1191 | B23: Munteanu | C23: Bianca | D23: F | E23: 27885 | F23: 45518 | G23: 40 | H23: Specialist HR | I23: Mid | J23: București | K23: Full-time | L23: 6100 | M23: Activ | P23: bianca.munteanu191@technova.ro | Q23: =_xlfn.XLOOKUP(angajati__2[[#This Row],[id_departament]],departamente!A:A,departamente!B:B) -> Resurse Umane | R23: =DATEDIF(E23,DATE(2025,12,31), "y") -> 49 | S23: =ROUND(YEARFRAC(F23, IF(M23="Plecat", N23, DATE(2025,12,31)), 1), 1) -> 1.4 | T23: {=_xlfn.IFS( S23<1, "< 1 an", S23<3, "1–3 ani", S23<5, "3–5 ani", S23>=5, "> 5 ani" )} -> 1–3 ani | U23: =IF(M23="Plecat", 1, 0) -> 0
A24: 1322 | B24: Stan | C24: Robert | D24: M | E24: 30718 | F24: 42689 | G24: 20 | H24: Key Account Manager | I24: Mid | J24: București | K24: Full-time | L24: 5700 | M24: Plecat | N24: 44180 | O24: Salariu mai bun în altă parte | P24: robert.stan322@technova.ro | Q24: =_xlfn.XLOOKUP(angajati__2[[#This Row],[id_departament]],departamente!A:A,departamente!B:B) -> Vânzări | R24: =DATEDIF(E24,DATE(2025,12,31), "y") -> 41 | S24: =ROUND(YEARFRAC(F24, IF(M24="Plecat", N24, DATE(2025,12,31)), 1), 1) -> 4.1 | T24: {=_xlfn.IFS( S24<1, "< 1 an", S24<3, "1–3 ani", S24<5, "3–5 ani", S24>=5, "> 5 ani" )} -> 3–5 ani | U24: =IF(M24="Plecat", 1, 0) -> 1
A25: 1403 | B25: Popescu | C25: Ionuț | D25: M | E25: 27222 | F25: 43492 | G25: 10 | H25: DevOps Engineer | I25: Senior | J25: București | K25: Full-time | L25: 14650 | M25: Activ | P25: ionut.popescu403@technova.ro | Q25: =_xlfn.XLOOKUP(angajati__2[[#This Row],[id_departament]],departamente!A:A,departamente!B:B) -> IT | R25: =DATEDIF(E25,DATE(2025,12,31), "y") -> 51 | S25: =ROUND(YEARFRAC(F25, IF(M25="Plecat", N25, DATE(2025,12,31)), 1), 1) -> 6.9 | T25: {=_xlfn.IFS( S25<1, "< 1 an", S25<3, "1–3 ani", S25<5, "3–5 ani", S25>=5, "> 5 ani" )} -> > 5 ani | U25: =IF(M25="Plecat", 1, 0) -> 0
A26: 1058 | B26: Ionescu | C26: Bogdan | D26: M | E26: 28282 | F26: 43315 | G26: 70 | H26: Coordonator Logistică | I26: Senior | J26: Timișoara | K26: Full-time | L26: 8150 | M26: Activ | P26: bogdan.ionescu058@technova.ro | Q26: =_xlfn.XLOOKUP(angajati__2[[#This Row],[id_departament]],departamente!A:A,departamente!B:B) -> Operațiuni | R26: =DATEDIF(E26,DATE(2025,12,31), "y") -> 48 | S26: =ROUND(YEARFRAC(F26, IF(M26="Plecat", N26, DATE(2025,12,31)), 1), 1) -> 7.4 | T26: {=_xlfn.IFS( S26<1, "< 1 an", S26<3, "1–3 ani", S26<5, "3–5 ani", S26>=5, "> 5 ani" )} -> > 5 ani | U26: =IF(M26="Plecat", 1, 0) -> 0
A27: 1300 | B27: Dinu | C27: Marius | D27: M | E27: 36678 | F27: 44467 | G27: 30 | H27: Content Creator | I27: Junior | J27: Cluj-Napoca | K27: Full-time | L27: 3400 | M27: Activ | P27: marius.dinu300@technova.ro | Q27: =_xlfn.XLOOKUP(angajati__2[[#This Row],[id_departament]],departamente!A:A,departamente!B:B) -> Marketing | R27: =DATEDIF(E27,DATE(2025,12,31), "y") -> 25 | S27: =ROUND(YEARFRAC(F27, IF(M27="Plecat", N27, DATE(2025,12,31)), 1), 1) -> 4.3 | T27: {=_xlfn.IFS( S27<1, "< 1 an", S27<3, "1–3 ani", S27<5, "3–5 ani", S27>=5, "> 5 ani" )} -> 3–5 ani | U27: =IF(M27="Plecat", 1, 0) -> 0
A28: 1125 | B28: Toma | C28: Robert | D28: M | E28: 35131 | F28: 43222 | G28: 70 | H28: Specialist Operațiuni | I28: Mid | J28: Timișoara | K28: Full-time | L28: 5450 | M28: Plecat | N28: 44578 | O28: Lipsa oportunităților de promovare | P28: robert.toma125@technova.ro | Q28: =_xlfn.XLOOKUP(angajati__2[[#This Row],[id_departament]],departamente!A:A,departamente!B:B) -> Operațiuni | R28: =DATEDIF(E28,DATE(2025,12,31), "y") -> 29 | S28: =ROUND(YEARFRAC(F28, IF(M28="Plecat", N28, DATE(2025,12,31)), 1), 1) -> 3.7 | T28: {=_xlfn.IFS( S28<1, "< 1 an", S28<3, "1–3 ani", S28<5, "3–5 ani", S28>=5, "> 5 ani" )} -> 3–5 ani | U28: =IF(M28="Plecat", 1, 0) -> 1
A29: 1318 | B29: Florea | C29: Denisa | D29: F | E29: 29751 | F29: 44298 | G29: 40 | H29: Recruiter | I29: Mid | J29: București | K29: Full-time | L29: 5100 | M29: Activ | P29: denisa.florea318@technova.ro | Q29: =_xlfn.XLOOKUP(angajati__2[[#This Row],[id_departament]],departamente!A:A,departamente!B:B) -> Resurse Umane | R29: =DATEDIF(E29,DATE(2025,12,31), "y") -> 44 | S29: =ROUND(YEARFRAC(F29, IF(M29="Plecat", N29, DATE(2025,12,31)), 1), 1) -> 4.7 | T29: {=_xlfn.IFS( S29<1, "< 1 an", S29<3, "1–3 ani", S29<5, "3–5 ani", S29>=5, "> 5 ani" )} -> 3–5 ani | U29: =IF(M29="Plecat", 1, 0) -> 0
A30: 1104 | B30: Gheorghe | C30: Diana | D30: F | E30: 33047 | F30: 43639 | G30: 50 | H30: Analist Financiar | I30: Mid | J30: București | K30: Full-time | L30: 6300 | M30: Activ | P30: diana.gheorghe104@technova.ro | Q30: =_xlfn.XLOOKUP(angajati__2[[#This Row],[id_departament]],departamente!A:A,departamente!B:B) -> Financiar | R30: =DATEDIF(E30,DATE(2025,12,31), "y") -> 35 | S30: =ROUND(YEARFRAC(F30, IF(M30="Plecat", N30, DATE(2025,12,31)), 1), 1) -> 6.5 | T30: {=_xlfn.IFS( S30<1, "< 1 an", S30<3, "1–3 ani", S30<5, "3–5 ani", S30>=5, "> 5 ani" )} -> > 5 ani | U30: =IF(M30="Plecat", 1, 0) -> 0
A31: 1156 | B31: Lungu | C31: Vlad | D31: M | E31: 35232 | F31: 44888 | G31: 20 | H31: Key Account Manager | I31: Junior | J31: Iași | K31: Full-time | L31: 3450 | M31: Activ | P31: vlad.lungu156@technova.ro | Q31: =_xlfn.XLOOKUP(angajati__2[[#This Row],[id_departament]],departamente!A:A,departamente!B:B) -> Vânzări | R31: =DATEDIF(E31,DATE(2025,12,31), "y") -> 29 | S31: =ROUND(YEARFRAC(F31, IF(M31="Plecat", N31, DATE(2025,12,31)), 1), 1) -> 3.1 | T31: {=_xlfn.IFS( S31<1, "< 1 an", S31<3, "1–3 ani", S31<5, "3–5 ani", S31>=5, "> 5 ani" )} -> 3–5 ani | U31: =IF(M31="Plecat", 1, 0) -> 0
A32: 1261 | B32: Gheorghe | C32: Alexandra | D32: F | E32: 30567 | F32: 44459 | G32: 60 | H32: Specialist Suport | I32: Junior | J32: Iași | K32: Full-time | L32: 2800 | M32: Activ | P32: alexandra.gheorghe261@technova.ro | Q32: =_xlfn.XLOOKUP(angajati__2[[#This Row],[id_departament]],departamente!A:A,departamente!B:B) -> Suport Clienți | R32: =DATEDIF(E32,DATE(2025,12,31), "y") -> 42 | S32: =ROUND(YEARFRAC(F32, IF(M32="Plecat", N32, DATE(2025,12,31)), 1), 1) -> 4.3 | T32: {=_xlfn.IFS( S32<1, "< 1 an", S32<3, "1–3 ani", S32<5, "3–5 ani", S32>=5, "> 5 ani" )} -> 3–5 ani | U32: =IF(M32="Plecat", 1, 0) -> 0
A33: 1379 | B33: Popescu | C33: Florin | D33: M | E33: 31800 | F33: 42764 | G33: 10 | H33: Programator | I33: Junior | J33: București | K33: Full-time | L33: 5750 | M33: Activ | P33: florin.popescu379@technova.ro | Q33: =_xlfn.XLOOKUP(angajati__2[[#This Row],[id_departament]],departamente!A:A,departamente!B:B) -> IT | R33: =DATEDIF(E33,DATE(2025,12,31), "y") -> 38 | S33: =ROUND(YEARFRAC(F33, IF(M33="Plecat", N33, DATE(2025,12,31)), 1), 1) -> 8.9 | T33: {=_xlfn.IFS( S33<1, "< 1 an", S33<3, "1–3 ani", S33<5, "3–5 ani", S33>=5, "> 5 ani" )} -> > 5 ani | U33: =IF(M33="Plecat", 1, 0) -> 0
A34: 1160 | B34: Nistor | C34: Roxana | D34: F | E34: 29909 | F34: 44968 | G34: 70 | H34: Coordonator Logistică | I34: Junior | J34: Timișoara | K34: Part-time | L34: 3100 | M34: Activ | P34: roxana.nistor160@technova.ro | Q34: =_xlfn.XLOOKUP(angajati__2[[#This Row],[id_departament]],departamente!A:A,departamente!B:B) -> Operațiuni | R34: =DATEDIF(E34,DATE(2025,12,31), "y") -> 44 | S34: =ROUND(YEARFRAC(F34, IF(M34="Plecat", N34, DATE(2025,12,31)), 1), 1) -> 2.9 | T34: {=_xlfn.IFS( S34<1, "< 1 an", S34<3, "1–3 ani", S34<5, "3–5 ani", S34>=5, "> 5 ani" )} -> 1–3 ani | U34: =IF(M34="Plecat", 1, 0) -> 0
A35: 1226 | B35: Popa | C35: Cristian | D35: M | E35: 34918 | F35: 42783 | G35: 10 | H35: Tester QA | I35: Junior | J35: Cluj-Napoca | K35: Full-time | L35: 5200 | M35: Activ | P35: cristian.popa226@technova.ro | Q35: =_xlfn.XLOOKUP(angajati__2[[#This Row],[id_departament]],departamente!A:A,departamente!B:B) -> IT | R35: =DATEDIF(E35,DATE(2025,12,31), "y") -> 30 | S35: =ROUND(YEARFRAC(F35, IF(M35="Plecat", N35, DATE(2025,12,31)), 1), 1) -> 8.9 | T35: {=_xlfn.IFS( S35<1, "< 1 an", S35<3, "1–3 ani", S35<5, "3–5 ani", S35>=5, "> 5 ani" )} -> > 5 ani | U35: =IF(M35="Plecat", 1, 0) -> 0
A36: 1464 | B36: Neagu | C36: Marius | D36: M | E36: 33576 | F36: 43071 | G36: 10 | H36: Programator | I36: Senior | J36: București | K36: Full-time | L36: 12350 | M36: Activ | P36: marius.neagu464@technova.ro | Q36: =_xlfn.XLOOKUP(angajati__2[[#This Row],[id_departament]],departamente!A:A,departamente!B:B) -> IT | R36: =DATEDIF(E36,DATE(2025,12,31), "y") -> 34 | S36: =ROUND(YEARFRAC(F36, IF(M36="Plecat", N36, DATE(2025,12,31)), 1), 1) -> 8.1 | T36: {=_xlfn.IFS( S36<1, "< 1 an", S36<3, "1–3 ani", S36<5, "3–5 ani", S36>=5, "> 5 ani" )} -> > 5 ani | U36: =IF(M36="Plecat", 1, 0) -> 0
A37: 1389 | B37: Dinu | C37: Vlad | D37: M | E37: 34852 | F37: 42928 | G37: 60 | H37: Specialist Suport | I37: Mid | J37: Iași | K37: Full-time | L37: 3900 | M37: Activ | P37: vlad.dinu389@technova.ro | Q37: =_xlfn.XLOOKUP(angajati__2[[#This Row],[id_departament]],departamente!A:A,departamente!B:B) -> Suport Clienți | R37: =DATEDIF(E37,DATE(2025,12,31), "y") -> 30 | S37: =ROUND(YEARFRAC(F37, IF(M37="Plecat", N37, DATE(2025,12,31)), 1), 1) -> 8.5 | T37: {=_xlfn.IFS( S37<1, "< 1 an", S37<3, "1–3 ani", S37<5, "3–5 ani", S37>=5, "> 5 ani" )} -> > 5 ani | U37: =IF(M37="Plecat", 1, 0) -> 0
A38: 1339 | B38: Nistor | C38: Sorin | D38: M | E38: 31256 | F38: 43593 | G38: 60 | H38: Specialist Suport | I38: Mid | J38: Iași | K38: Full-time | L38: 4250 | M38: Activ | P38: sorin.nistor339@technova.ro | Q38: =_xlfn.XLOOKUP(angajati__2[[#This Row],[id_departament]],departamente!A:A,departamente!B:B) -> Suport Clienți | R38: =DATEDIF(E38,DATE(2025,12,31), "y") -> 40 | S38: =ROUND(YEARFRAC(F38, IF(M38="Plecat", N38, DATE(2025,12,31)), 1), 1) -> 6.6 | T38: {=_xlfn.IFS( S38<1, "< 1 an", S38<3, "1–3 ani", S38<5, "3–5 ani", S38>=5, "> 5 ani" )} -> > 5 ani | U38: =IF(M38="Plecat", 1, 0) -> 0
A39: 1229 | B39: Constantin | C39: Mihai | D39: M | E39: 27503 | F39: 43908 | G39: 50 | H39: Manager Financiar | I39: Manager | J39: Timișoara | K39: Full-time | L39: 14050 | M39: Activ | P39: mihai.constantin229@technova.ro | Q39: =_xlfn.XLOOKUP(angajati__2[[#This Row],[id_departament]],departamente!A:A,departamente!B:B) -> Financiar | R39: =DATEDIF(E39,DATE(2025,12,31), "y") -> 50 | S39: =ROUND(YEARFRAC(F39, IF(M39="Plecat", N39, DATE(2025,12,31)), 1), 1) -> 5.8 | T39: {=_xlfn.IFS( S39<1, "< 1 an", S39<3, "1–3 ani", S39<5, "3–5 ani", S39>=5, "> 5 ani" )} -> > 5 ani | U39: =IF(M39="Plecat", 1, 0) -> 0
A40: 1088 | B40: Oprea | C40: Alexandru | D40: M | E40: 31743 | F40: 45600 | G40: 20 | H40: Manager Vânzări | I40: Manager | J40: Iași | K40: Full-time | L40: 9150 | M40: Activ | P40: alexandru.oprea088@technova.ro | Q40: =_xlfn.XLOOKUP(angajati__2[[#This Row],[id_departament]],departamente!A:A,departamente!B:B) -> Vânzări | R40: =DATEDIF(E40,DATE(2025,12,31), "y") -> 39 | S40: =ROUND(YEARFRAC(F40, IF(M40="Plecat", N40, DATE(2025,12,31)), 1), 1) -> 1.2 | T40: {=_xlfn.IFS( S40<1, "< 1 an", S40<3, "1–3 ani", S40<5, "3–5 ani", S40>=5, "> 5 ani" )} -> 1–3 ani | U40: =IF(M40="Plecat", 1, 0) -> 0
... A42: 1463 | B42: Tudor | C42: Ana | D42: F | E42: 30359 | F42: 44724 | G42: 10 | H42: DevOps Engineer | I42: Senior | J42: București | K42: Full-time | L42: 12200 | M42: Activ | P42: ana.tudor463@technova.ro | Q42: =_xlfn.XLOOKUP(angajati__2[[#This Row],[id_departament]],departamente!A:A,departamente!B:B) -> IT | R42: =DATEDIF(E42,DATE(2025,12,31), "y") -> 42 | S42: =ROUND(YEARFRAC(F42, IF(M42="Plecat", N42, DATE(2025,12,31)), 1), 1) -> 3.6 | T42: {=_xlfn.IFS( S42<1, "< 1 an", S42<3, "1–3 ani", S42<5, "3–5 ani", S42>=5, "> 5 ani" )} -> 3–5 ani | U42: =IF(M42="Plecat", 1, 0) -> 0
...

Sheet pivot
A2: Date extrase din tab-ul angajati_curat
A3: Numarul de angajati pe departament si nivel
A4: Count of id_angajat | B4: nivel
A5: nume_departament | B5: Junior | C5: Manager | D5: Mid | E5: Senior | F5: Grand Total
A6: Financiar | B6: 12 | C6: 3 | D6: 15 | E6: 6 | F6: 36
A7: IT | B7: 46 | C7: 10 | D7: 31 | E7: 25 | F7: 112
A8: Juridic | B8: 5 | D8: 8 | E8: 3 | F8: 16
A9: Marketing | B9: 13 | C9: 2 | D9: 15 | E9: 13 | F9: 43
A10: Operațiuni | B10: 19 | C10: 5 | D10: 33 | E10: 22 | F10: 79
A11: Resurse Umane | B11: 6 | C11: 1 | D11: 13 | E11: 5 | F11: 25
A12: Suport Clienți | B12: 24 | C12: 5 | D12: 31 | E12: 25 | F12: 85
A13: Vânzări | B13: 32 | C13: 9 | D13: 28 | E13: 15 | F13: 84
A14: Grand Total | B14: 157 | C14: 35 | D14: 174 | E14: 114 | F14: 480
A16: Salariul mediu pe departament si nivel
A17: Average of salariu_brut_lunar | B17: nivel
A18: nume_departament | B18: Junior | C18: Manager | D18: Mid | E18: Senior | F18: Grand Total
A19: Financiar | B19: 4708.3333 | C19: 13083.333 | D19: 6748.3333 | E19: 9325 | F19: 7025.6944
A20: IT | B20: 6169.5652 | C20: 16645 | D20: 8522.5806 | E20: 12986 | F20: 9277.6786
A21: Juridic | B21: 5230 | D21: 7818.75 | E21: 11183.333 | F21: 7640.625
A22: Marketing | B22: 3973.0769 | C22: 10175 | D22: 6140 | E22: 8813.4615 | F22: 6480.814
A23: Operațiuni | B23: 3626.3158 | C23: 10220 | D23: 5002.2727 | E23: 7684.0909 | F23: 5748.4177
A24: Resurse Umane | B24: 3841.6667 | C24: 11200 | D24: 5657.6923 | E24: 8620 | F24: 6036
A25: Suport Clienți | B25: 2843.75 | C25: 8110 | D25: 4134.6774 | E25: 6032 | F25: 4562.0588
A26: Vânzări | B26: 3770.3125 | C26: 10022.222 | D26: 5319.6429 | E26: 7786.6667 | F26: 5673.8095
A27: Grand Total | B27: 4451.9108 | C27: 11974.286 | D27: 5953.0172 | E27: 8846.2719 | F27: 6588.2292
A29: Rata de plecare per departament
A30: nume_departament | B30: Average of plecat
A31: Resurse Umane | B31: 0.12
A32: IT | B32: 0.16071429
A33: Operațiuni | B33: 0.16455696
A34: Financiar | B34: 0.19444444
A35: Marketing | B35: 0.23255814
A36: Juridic | B36: 0.25
A37: Suport Clienți | B37: 0.31764706
A38: Vânzări | B38: 0.39285714
A39: Grand Total | B39: 0.23958333

Sheet jurnal_curatare
A1: Coloana | B1: Problema | C1: Cate cazuri | D1: Ce am facut
A2: id_angajat!A1 | B2: Randuri duplicate | C2: 12 | D2: Data-Remove duplicates pe toate coloanele.
A3: nume!B1, prenume!C1 | B3: Spatii inainte sau dupa nume/prenume | C3: Valori pe 2 coloane | D3: Am folosit formula TRIM pe coloanele nume si prenume.
A4: nume!B1, prenume!C1 | B4: Nume si prenume scrise incorect | C4: Valori pe 2 coloane | D4: Am folosit formula PROPER pe coloanele nume, prenume, nivel si status.
A5: gen!D1, oras!J1, nivel!I1, status!M1 | B5: Valori nestandardizate pe coloanele gen, oras , nivel si status | C5: Valori pe 4 coloane | D5: Am folosit TRIM ce curata spatiile, UPPER/LOWER uniformizeaza textul, LEFT verifica primele litere, iar IF transformă toate variantele într-o singură forma standard. De asemenea, am folosit PROPER pentru nivel si status, pentru a avea doar termeni cu litera mare la inceput.
A6: data_nasterii!E1, data_angajarii!F1, data_plecarii!N1 | B6: Coerenta date | C6: Valori pe 3 coloane | D6: Pentru coerenta datelor de formatul zz.ll.aaaa, am folosit DATE cu LEFT/MID/RIGHT.
A7: id_departament!G1 | B7: 8 angajati nu au id_departament | C7: 8 | D7: Am folosit =IF(G2<>"", G2, XLOOKUP(H2, H:H, G:G)), unde daca G2 are deja un departament, atunci il pastreaza; iar daca G2 este gol, atunci cauta in tabel alti angajati cu aceeasi functie si returneaza departamentul lor.
A8: salariu_brut_lunar!L1 | B8: O valoare negativa si 2 valori prea mari pe coloana salariu_brut_lunar | C8: 1,2 | D8: Am folosit formula =IF(L2<=0, ABS(L2), IF(L2>30000, IF(L2/10 <= AVERAGEIFS($L:$L, $G:$G, G2, $I:$I, I2), L2/10, IF(L2/100 <= AVERAGEIFS($L:$L, $G:$G, G2, $I:$I, I2), L2/100, L2)), L2)). Daca salariul este negativ, il fac pozitiv; daca este mai mare de 30,000, incerc sa-l corectez impartindu-l la 10 sau la 100, dar doar daca noua valoare se potriveste cu salariile obisnuite din acelasi departament si nivel; altfel il las neschimbat.
A9: salariu_brut_lunar!L1 | B9: Salarii cu valoarea 0 | C9: 19 | D9: Am sters valorile de 0 si le-am tratat ca lipsa. Am folosit formula =IF(L2="", MEDIAN(FILTER($L$2:$L$481, ($G$2:$G$481=G2)*($I$2:$I$481=I2)*($L$2:$L$481<>""))), L2). Daca salariul lipseste, il completez cu mediana salariilor din acelasi departament si nivel; daca salariul exista, il las neschimbat.
A10: motiv_plecare!O1 | B10: Randuri fara motiv plecare | C10: 12 | D10: Am folosit formula =IF(AND(M7="Plecat", O7=""), "Nespecificat", O7). Daca angajatul este plecat si motivul plecarii lipseste, completez cu “Nespecificat”; altfel pastrez valoarea originala.
A11: email!P1 | B11: Randuri fara e-mail | C11: 10 | D11: Cu ajutorului unui =COUNTBLANK(P2:P481), am vazut ca sunt 10 randuri fara e-mail.
